2022-04-12 22:12:35,849 INFO this is a start of my code and i am try to fetch data from web 
2022-04-12 22:12:35,864 DEBUG Starting new HTTPS connection (1): covid19.apple.com:443
2022-04-12 22:12:36,736 DEBUG https://covid19.apple.com:443 "GET /mobility.com HTTP/1.1" 404 1529
2022-04-12 22:12:56,048 ERROR Errog has happend 
2022-04-12 22:12:56,048 ERROR Exception occured check_dir() missing 1 required positional argument: 'data_frame'
Traceback (most recent call last):
  File "D:\ts-mesh-pipeline\dummy-data-product\src\dependencies\scraping\scraper.py", line 36, in wsc
    check_dir()
TypeError: check_dir() missing 1 required positional argument: 'data_frame'
2022-04-12 22:14:28,923 INFO this is a start of my code and i am try to fetch data from web 
2022-04-12 22:14:28,923 DEBUG Starting new HTTPS connection (1): covid19.apple.com:443
2022-04-12 22:14:29,919 DEBUG https://covid19.apple.com:443 "GET /mobility.com HTTP/1.1" 404 1529
2022-04-12 22:14:49,006 ERROR Errog has happend 
2022-04-12 22:14:49,006 ERROR Exception occured check_dir() missing 1 required positional argument: 'data_frame'
Traceback (most recent call last):
  File "D:\ts-mesh-pipeline\dummy-data-product\src\dependencies\scraping\scraper.py", line 36, in wsc
    check_dir()
TypeError: check_dir() missing 1 required positional argument: 'data_frame'
2022-04-12 22:26:47,284 INFO this is a start of my code and i am try to fetch data from web 
2022-04-12 22:26:47,284 DEBUG Starting new HTTPS connection (1): covid19.apple.com:443
2022-04-12 22:26:48,472 DEBUG https://covid19.apple.com:443 "GET /mobility.com HTTP/1.1" 404 1529
2022-04-12 22:27:08,863 ERROR Errog has happend 
2022-04-12 22:27:08,863 ERROR Exception occured check_dir() missing 1 required positional argument: 'data_frame'
Traceback (most recent call last):
  File "D:\ts-mesh-pipeline\dummy-data-product\src\dependencies\scraping\scraper.py", line 36, in wsc
    check_dir()
TypeError: check_dir() missing 1 required positional argument: 'data_frame'
2022-04-12 22:40:02,898 INFO this is a start of my code and i am try to fetch data from web 
2022-04-12 22:40:02,898 DEBUG Starting new HTTPS connection (1): covid19.apple.com:443
2022-04-12 22:40:03,684 DEBUG https://covid19.apple.com:443 "GET /mobility.com HTTP/1.1" 404 1529
2022-04-12 22:40:18,205 ERROR Errog has happend 
2022-04-12 22:40:18,205 ERROR Exception occured check_dir() missing 1 required positional argument: 'data_frame'
Traceback (most recent call last):
  File "D:\ts-mesh-pipeline\dummy-data-product\src\dependencies\scraping\scraper.py", line 42, in wsc
    check_dir()
TypeError: check_dir() missing 1 required positional argument: 'data_frame'
2022-04-12 22:48:51,102 INFO this is a start of my code and i am try to fetch data from web 
2022-04-12 22:48:51,102 DEBUG Starting new HTTPS connection (1): covid19.apple.com:443
2022-04-12 22:48:52,265 DEBUG https://covid19.apple.com:443 "GET /mobility.com HTTP/1.1" 404 1529
2022-04-12 22:49:16,967 ERROR Errog has happend 
2022-04-12 22:49:16,967 ERROR Exception occured check_dir() missing 1 required positional argument: 'data_frame'
Traceback (most recent call last):
  File "D:\ts-mesh-pipeline\dummy-data-product\src\dependencies\scraping\scraper.py", line 41, in wsc
    check_dir()
TypeError: check_dir() missing 1 required positional argument: 'data_frame'
2022-04-13 19:57:20,829 INFO this is a start of my code and i am try to fetch data from web 
2022-04-13 19:57:20,876 DEBUG Starting new HTTPS connection (1): covid19.apple.com:443
2022-04-13 19:57:20,881 ERROR Errog has happend 
2022-04-13 19:57:20,881 ERROR Exception occured HTTPSConnectionPool(host='covid19.apple.com', port=443): Max retries exceeded with url: /mobility.com (Caused by NewConnectionError('<urllib3.connection.HTTPSConnection object at 0x0000029A2A3B66A0>: Failed to establish a new connection: [Errno 11001] getaddrinfo failed'))
Traceback (most recent call last):
  File "D:\ANNACONDA\envs\ts-mesh-pipeline\lib\site-packages\urllib3\connection.py", line 174, in _new_conn
    conn = connection.create_connection(
  File "D:\ANNACONDA\envs\ts-mesh-pipeline\lib\site-packages\urllib3\util\connection.py", line 72, in create_connection
    for res in socket.getaddrinfo(host, port, family, socket.SOCK_STREAM):
  File "D:\ANNACONDA\envs\ts-mesh-pipeline\lib\socket.py", line 954, in getaddrinfo
    for res in _socket.getaddrinfo(host, port, family, type, proto, flags):
socket.gaierror: [Errno 11001] getaddrinfo failed

During handling of the above exception, another exception occurred:

Traceback (most recent call last):
  File "D:\ANNACONDA\envs\ts-mesh-pipeline\lib\site-packages\urllib3\connectionpool.py", line 703, in urlopen
    httplib_response = self._make_request(
  File "D:\ANNACONDA\envs\ts-mesh-pipeline\lib\site-packages\urllib3\connectionpool.py", line 386, in _make_request
    self._validate_conn(conn)
  File "D:\ANNACONDA\envs\ts-mesh-pipeline\lib\site-packages\urllib3\connectionpool.py", line 1040, in _validate_conn
    conn.connect()
  File "D:\ANNACONDA\envs\ts-mesh-pipeline\lib\site-packages\urllib3\connection.py", line 358, in connect
    self.sock = conn = self._new_conn()
  File "D:\ANNACONDA\envs\ts-mesh-pipeline\lib\site-packages\urllib3\connection.py", line 186, in _new_conn
    raise NewConnectionError(
urllib3.exceptions.NewConnectionError: <urllib3.connection.HTTPSConnection object at 0x0000029A2A3B66A0>: Failed to establish a new connection: [Errno 11001] getaddrinfo failed

During handling of the above exception, another exception occurred:

Traceback (most recent call last):
  File "D:\ANNACONDA\envs\ts-mesh-pipeline\lib\site-packages\requests\adapters.py", line 440, in send
    resp = conn.urlopen(
  File "D:\ANNACONDA\envs\ts-mesh-pipeline\lib\site-packages\urllib3\connectionpool.py", line 785, in urlopen
    retries = retries.increment(
  File "D:\ANNACONDA\envs\ts-mesh-pipeline\lib\site-packages\urllib3\util\retry.py", line 592, in increment
    raise MaxRetryError(_pool, url, error or ResponseError(cause))
urllib3.exceptions.MaxRetryError: HTTPSConnectionPool(host='covid19.apple.com', port=443): Max retries exceeded with url: /mobility.com (Caused by NewConnectionError('<urllib3.connection.HTTPSConnection object at 0x0000029A2A3B66A0>: Failed to establish a new connection: [Errno 11001] getaddrinfo failed'))

During handling of the above exception, another exception occurred:

Traceback (most recent call last):
  File "D:\ts-mesh-pipeline\dummy-data-product\src\dependencies\scraping\scraper.py", line 21, in wsc
    url = requests.get("https://covid19.apple.com/mobility.com")
  File "D:\ANNACONDA\envs\ts-mesh-pipeline\lib\site-packages\requests\api.py", line 75, in get
    return request('get', url, params=params, **kwargs)
  File "D:\ANNACONDA\envs\ts-mesh-pipeline\lib\site-packages\requests\api.py", line 61, in request
    return session.request(method=method, url=url, **kwargs)
  File "D:\ANNACONDA\envs\ts-mesh-pipeline\lib\site-packages\requests\sessions.py", line 529, in request
    resp = self.send(prep, **send_kwargs)
  File "D:\ANNACONDA\envs\ts-mesh-pipeline\lib\site-packages\requests\sessions.py", line 645, in send
    r = adapter.send(request, **kwargs)
  File "D:\ANNACONDA\envs\ts-mesh-pipeline\lib\site-packages\requests\adapters.py", line 519, in send
    raise ConnectionError(e, request=request)
requests.exceptions.ConnectionError: HTTPSConnectionPool(host='covid19.apple.com', port=443): Max retries exceeded with url: /mobility.com (Caused by NewConnectionError('<urllib3.connection.HTTPSConnection object at 0x0000029A2A3B66A0>: Failed to establish a new connection: [Errno 11001] getaddrinfo failed'))
2022-04-13 21:32:18,903 INFO this is a start of my code and i am try to fetch data from web 
2022-04-13 21:32:18,926 DEBUG Starting new HTTPS connection (1): covid19.apple.com:443
2022-04-13 21:32:19,929 DEBUG https://covid19.apple.com:443 "GET /mobility.com HTTP/1.1" 404 1529
2022-04-13 21:32:34,290 ERROR Errog has happend 
2022-04-13 21:32:34,291 ERROR Exception occured check_dir() missing 1 required positional argument: 'data_frame'
Traceback (most recent call last):
  File "D:\ts-mesh-pipeline\dummy-data-product\src\dependencies\scraping\scraper.py", line 41, in wsc
    check_dir()
TypeError: check_dir() missing 1 required positional argument: 'data_frame'
2022-04-13 21:33:54,752 INFO this is a start of my code and i am try to fetch data from web 
2022-04-13 21:33:54,790 DEBUG Starting new HTTPS connection (1): covid19.apple.com:443
2022-04-13 21:33:55,937 DEBUG https://covid19.apple.com:443 "GET /mobility.com HTTP/1.1" 404 1529
2022-04-13 21:34:11,281 ERROR Errog has happend 
2022-04-13 21:34:11,281 ERROR Exception occured check_dir() missing 1 required positional argument: 'data_frame'
Traceback (most recent call last):
  File "D:\ts-mesh-pipeline\dummy-data-product\src\dependencies\scraping\scraper.py", line 41, in wsc
    check_dir()
TypeError: check_dir() missing 1 required positional argument: 'data_frame'
2022-04-13 21:34:22,423 INFO this is a start of my code and i am try to fetch data from web 
2022-04-13 21:34:22,434 DEBUG Starting new HTTPS connection (1): covid19.apple.com:443
2022-04-13 21:34:22,932 DEBUG https://covid19.apple.com:443 "GET /mobility.com HTTP/1.1" 404 1529
2022-04-13 21:34:48,789 ERROR Errog has happend 
2022-04-13 21:34:48,790 ERROR Exception occured check_dir() missing 1 required positional argument: 'data_frame'
Traceback (most recent call last):
  File "D:\ts-mesh-pipeline\dummy-data-product\src\dependencies\scraping\scraper.py", line 41, in wsc
    check_dir()
TypeError: check_dir() missing 1 required positional argument: 'data_frame'
2022-04-14 18:41:04,354 INFO this is a start of my code and i am try to fetch data from web 
2022-04-14 18:41:04,354 DEBUG Starting new HTTPS connection (1): covid19.apple.com:443
2022-04-14 18:41:05,128 DEBUG https://covid19.apple.com:443 "GET /mobility.com HTTP/1.1" 404 1529
2022-04-14 18:41:15,962 ERROR Errog has happend 
2022-04-14 18:41:15,962 ERROR Exception occured check_dir() missing 1 required positional argument: 'data_frame'
Traceback (most recent call last):
  File "D:\ts-mesh-pipeline\dummy-data-product\src\dependencies\scraping\scraper.py", line 41, in wsc
    check_dir()
TypeError: check_dir() missing 1 required positional argument: 'data_frame'
